Workbook

Sheet DomainOps
A1: domain | B1: operation | C1: domain_op_key | D1: is_supported | E1: source_url
A2: calendar | B2: count | C2: =A2&"|"&B2 | D2: =IF(AND(A2<>"",B2<>""),1,0) | E2: file:///Users/sagalilja/Library/Mobile%20Documents/com~apple~CloudDocs/Helper/backend/docs/domain_operation_table.csv
A3: calendar | B3: list | C3: =A3&"|"&B3 | D3: =IF(AND(A3<>"",B3<>""),1,0) | E3: file:///Users/sagalilja/Library/Mobile%20Documents/com~apple~CloudDocs/Helper/backend/docs/domain_operation_table.csv
A4: calendar | B4: exists | C4: =A4&"|"&B4 | D4: =IF(AND(A4<>"",B4<>""),1,0) | E4: file:///Users/sagalilja/Library/Mobile%20Documents/com~apple~CloudDocs/Helper/backend/docs/domain_operation_table.csv
A5: calendar | B5: sum | C5: =A5&"|"&B5 | D5: =IF(AND(A5<>"",B5<>""),1,0) | E5: file:///Users/sagalilja/Library/Mobile%20Documents/com~apple~CloudDocs/Helper/backend/docs/domain_operation_table.csv
A6: calendar | B6: latest | C6: =A6&"|"&B6 | D6: =IF(AND(A6<>"",B6<>""),1,0) | E6: file:///Users/sagalilja/Library/Mobile%20Documents/com~apple~CloudDocs/Helper/backend/docs/domain_operation_table.csv
A7: reminders | B7: count | C7: =A7&"|"&B7 | D7: =IF(AND(A7<>"",B7<>""),1,0) | E7: file:///Users/sagalilja/Library/Mobile%20Documents/com~apple~CloudDocs/Helper/backend/docs/domain_operation_table.csv
A8: reminders | B8: list | C8: =A8&"|"&B8 | D8: =IF(AND(A8<>"",B8<>""),1,0) | E8: file:///Users/sagalilja/Library/Mobile%20Documents/com~apple~CloudDocs/Helper/backend/docs/domain_operation_table.csv
A9: reminders | B9: exists | C9: =A9&"|"&B9 | D9: =IF(AND(A9<>"",B9<>""),1,0) | E9: file:///Users/sagalilja/Library/Mobile%20Documents/com~apple~CloudDocs/Helper/backend/docs/domain_operation_table.csv
A10: reminders | B10: sum | C10: =A10&"|"&B10 | D10: =IF(AND(A10<>"",B10<>""),1,0) | E10: file:///Users/sagalilja/Library/Mobile%20Documents/com~apple~CloudDocs/Helper/backend/docs/domain_operation_table.csv
A11: reminders | B11: latest | C11: =A11&"|"&B11 | D11: =IF(AND(A11<>"",B11<>""),1,0) | E11: file:///Users/sagalilja/Library/Mobile%20Documents/com~apple~CloudDocs/Helper/backend/docs/domain_operation_table.csv
A12: mail | B12: count | C12: =A12&"|"&B12 | D12: =IF(AND(A12<>"",B12<>""),1,0) | E12: file:///Users/sagalilja/Library/Mobile%20Documents/com~apple~CloudDocs/Helper/backend/docs/domain_operation_table.csv
A13: mail | B13: list | C13: =A13&"|"&B13 | D13: =IF(AND(A13<>"",B13<>""),1,0) | E13: file:///Users/sagalilja/Library/Mobile%20Documents/com~apple~CloudDocs/Helper/backend/docs/domain_operation_table.csv
... A46: memory | B46: latest | C46: =A46&"|"&B46 | D46: =IF(AND(A46<>"",B46<>""),1,0) | E46: file:///Users/sagalilja/Library/Mobile%20Documents/com~apple~CloudDocs/Helper/backend/docs/domain_operation_table.csv

Sheet IntentCombinations
A1: domain | B1: operation | C1: time_type | D1: time_value | E1: mode | F1: filters | G1: combo_key | H1: is_all | I1: is_relative | J1: row_valid | K1: duplicate_count | L1: has_duplicate | M1: source_url
A2: calendar | B2: count | C2: all | E2: info | F2: {} | G2: =A2&"|"&B2&"|"&C2&"|"&IF(D2="","(none)",D2) | H2: =--(C2="all") | I2: =--(C2="relative") | J2: =IF(AND(A2<>"",B2<>"",C2<>""),1,0) | K2: =COUNTIF($G$2:$G$496,G2) | L2: =IF(K2>1,1,0) | M2: file:///Users/sagalilja/Library/Mobile%20Documents/com~apple~CloudDocs/Helper/backend/backend/docs/intent_combinations.csv
A3: calendar | B3: count | C3: relative | D3: today | E3: info | F3: {} | G3: =A3&"|"&B3&"|"&C3&"|"&IF(D3="","(none)",D3) | H3: =--(C3="all") | I3: =--(C3="relative") | J3: =IF(AND(A3<>"",B3<>"",C3<>""),1,0) | K3: =COUNTIF($G$2:$G$496,G3) | L3: =IF(K3>1,1,0) | M3: file:///Users/sagalilja/Library/Mobile%20Documents/com~apple~CloudDocs/Helper/backend/backend/docs/intent_combinations.csv
A4: calendar | B4: count | C4: relative | D4: today_morning | E4: info | F4: {} | G4: =A4&"|"&B4&"|"&C4&"|"&IF(D4="","(none)",D4) | H4: =--(C4="all") | I4: =--(C4="relative") | J4: =IF(AND(A4<>"",B4<>"",C4<>""),1,0) | K4: =COUNTIF($G$2:$G$496,G4) | L4: =IF(K4>1,1,0) | M4: file:///Users/sagalilja/Library/Mobile%20Documents/com~apple~CloudDocs/Helper/backend/backend/docs/intent_combinations.csv
A5: calendar | B5: count | C5: relative | D5: today_day | E5: info | F5: {} | G5: =A5&"|"&B5&"|"&C5&"|"&IF(D5="","(none)",D5) | H5: =--(C5="all") | I5: =--(C5="relative") | J5: =IF(AND(A5<>"",B5<>"",C5<>""),1,0) | K5: =COUNTIF($G$2:$G$496,G5) | L5: =IF(K5>1,1,0) | M5: file:///Users/sagalilja/Library/Mobile%20Documents/com~apple~CloudDocs/Helper/backend/backend/docs/intent_combinations.csv
A6: calendar | B6: count | C6: relative | D6: today_afternoon | E6: info | F6: {} | G6: =A6&"|"&B6&"|"&C6&"|"&IF(D6="","(none)",D6) | H6: =--(C6="all") | I6: =--(C6="relative") | J6: =IF(AND(A6<>"",B6<>"",C6<>""),1,0) | K6: =COUNTIF($G$2:$G$496,G6) | L6: =IF(K6>1,1,0) | M6: file:///Users/sagalilja/Library/Mobile%20Documents/com~apple~CloudDocs/Helper/backend/backend/docs/intent_combinations.csv
A7: calendar | B7: count | C7: relative | D7: today_evening | E7: info | F7: {} | G7: =A7&"|"&B7&"|"&C7&"|"&IF(D7="","(none)",D7) | H7: =--(C7="all") | I7: =--(C7="relative") | J7: =IF(AND(A7<>"",B7<>"",C7<>""),1,0) | K7: =COUNTIF($G$2:$G$496,G7) | L7: =IF(K7>1,1,0) | M7: file:///Users/sagalilja/Library/Mobile%20Documents/com~apple~CloudDocs/Helper/backend/backend/docs/intent_combinations.csv
A8: calendar | B8: count | C8: relative | D8: tomorrow_morning | E8: info | F8: {} | G8: =A8&"|"&B8&"|"&C8&"|"&IF(D8="","(none)",D8) | H8: =--(C8="all") | I8: =--(C8="relative") | J8: =IF(AND(A8<>"",B8<>"",C8<>""),1,0) | K8: =COUNTIF($G$2:$G$496,G8) | L8: =IF(K8>1,1,0) | M8: file:///Users/sagalilja/Library/Mobile%20Documents/com~apple~CloudDocs/Helper/backend/backend/docs/intent_combinations.csv
A9: calendar | B9: count | C9: relative | D9: 7d | E9: info | F9: {} | G9: =A9&"|"&B9&"|"&C9&"|"&IF(D9="","(none)",D9) | H9: =--(C9="all") | I9: =--(C9="relative") | J9: =IF(AND(A9<>"",B9<>"",C9<>""),1,0) | K9: =COUNTIF($G$2:$G$496,G9) | L9: =IF(K9>1,1,0) | M9: file:///Users/sagalilja/Library/Mobile%20Documents/com~apple~CloudDocs/Helper/backend/backend/docs/intent_combinations.csv
A10: calendar | B10: count | C10: relative | D10: 30d | E10: info | F10: {} | G10: =A10&"|"&B10&"|"&C10&"|"&IF(D10="","(none)",D10) | H10: =--(C10="all") | I10: =--(C10="relative") | J10: =IF(AND(A10<>"",B10<>"",C10<>""),1,0) | K10: =COUNTIF($G$2:$G$496,G10) | L10: =IF(K10>1,1,0) | M10: file:///Users/sagalilja/Library/Mobile%20Documents/com~apple~CloudDocs/Helper/backend/backend/docs/intent_combinations.csv
A11: calendar | B11: count | C11: relative | D11: 3m | E11: info | F11: {} | G11: =A11&"|"&B11&"|"&C11&"|"&IF(D11="","(none)",D11) | H11: =--(C11="all") | I11: =--(C11="relative") | J11: =IF(AND(A11<>"",B11<>"",C11<>""),1,0) | K11: =COUNTIF($G$2:$G$496,G11) | L11: =IF(K11>1,1,0) | M11: file:///Users/sagalilja/Library/Mobile%20Documents/com~apple~CloudDocs/Helper/backend/backend/docs/intent_combinations.csv
A12: calendar | B12: count | C12: relative | D12: 1y | E12: info | F12: {} | G12: =A12&"|"&B12&"|"&C12&"|"&IF(D12="","(none)",D12) | H12: =--(C12="all") | I12: =--(C12="relative") | J12: =IF(AND(A12<>"",B12<>"",C12<>""),1,0) | K12: =COUNTIF($G$2:$G$496,G12) | L12: =IF(K12>1,1,0) | M12: file:///Users/sagalilja/Library/Mobile%20Documents/com~apple~CloudDocs/Helper/backend/backend/docs/intent_combinations.csv
A13: calendar | B13: list | C13: all | E13: info | F13: {} | G13: =A13&"|"&B13&"|"&C13&"|"&IF(D13="","(none)",D13) | H13: =--(C13="all") | I13: =--(C13="relative") | J13: =IF(AND(A13<>"",B13<>"",C13<>""),1,0) | K13: =COUNTIF($G$2:$G$496,G13) | L13: =IF(K13>1,1,0) | M13: file:///Users/sagalilja/Library/Mobile%20Documents/com~apple~CloudDocs/Helper/backend/backend/docs/intent_combinations.csv
A14: calendar | B14: list | C14: relative | D14: today | E14: info | F14: {} | G14: =A14&"|"&B14&"|"&C14&"|"&IF(D14="","(none)",D14) | H14: =--(C14="all") | I14: =--(C14="relative") | J14: =IF(AND(A14<>"",B14<>"",C14<>""),1,0) | K14: =COUNTIF($G$2:$G$496,G14) | L14: =IF(K14>1,1,0) | M14: file:///Users/sagalilja/Library/Mobile%20Documents/com~apple~CloudDocs/Helper/backend/backend/docs/intent_combinations.csv
A15: calendar | B15: list | C15: relative | D15: today_morning | E15: info | F15: {} | G15: =A15&"|"&B15&"|"&C15&"|"&IF(D15="","(none)",D15) | H15: =--(C15="all") | I15: =--(C15="relative") | J15: =IF(AND(A15<>"",B15<>"",C15<>""),1,0) | K15: =COUNTIF($G$2:$G$496,G15) | L15: =IF(K15>1,1,0) | M15: file:///Users/sagalilja/Library/Mobile%20Documents/com~apple~CloudDocs/Helper/backend/backend/docs/intent_combinations.csv
A16: calendar | B16: list | C16: relative | D16: today_day | E16: info | F16: {} | G16: =A16&"|"&B16&"|"&C16&"|"&IF(D16="","(none)",D16) | H16: =--(C16="all") | I16: =--(C16="relative") | J16: =IF(AND(A16<>"",B16<>"",C16<>""),1,0) | K16: =COUNTIF($G$2:$G$496,G16) | L16: =IF(K16>1,1,0) | M16: file:///Users/sagalilja/Library/Mobile%20Documents/com~apple~CloudDocs/Helper/backend/backend/docs/intent_combinations.csv
A17: calendar | B17: list | C17: relative | D17: today_afternoon | E17: info | F17: {} | G17: =A17&"|"&B17&"|"&C17&"|"&IF(D17="","(none)",D17) | H17: =--(C17="all") | I17: =--(C17="relative") | J17: =IF(AND(A17<>"",B17<>"",C17<>""),1,0) | K17: =COUNTIF($G$2:$G$496,G17) | L17: =IF(K17>1,1,0) | M17: file:///Users/sagalilja/Library/Mobile%20Documents/com~apple~CloudDocs/Helper/backend/backend/docs/intent_combinations.csv
A18: calendar | B18: list | C18: relative | D18: today_evening | E18: info | F18: {} | G18: =A18&"|"&B18&"|"&C18&"|"&IF(D18="","(none)",D18) | H18: =--(C18="all") | I18: =--(C18="relative") | J18: =IF(AND(A18<>"",B18<>"",C18<>""),1,0) | K18: =COUNTIF($G$2:$G$496,G18) | L18: =IF(K18>1,1,0) | M18: file:///Users/sagalilja/Library/Mobile%20Documents/com~apple~CloudDocs/Helper/backend/backend/docs/intent_combinations.csv
A19: calendar | B19: list | C19: relative | D19: tomorrow_morning | E19: info | F19: {} | G19: =A19&"|"&B19&"|"&C19&"|"&IF(D19="","(none)",D19) | H19: =--(C19="all") | I19: =--(C19="relative") | J19: =IF(AND(A19<>"",B19<>"",C19<>""),1,0) | K19: =COUNTIF($G$2:$G$496,G19) | L19: =IF(K19>1,1,0) | M19: file:///Users/sagalilja/Library/Mobile%20Documents/com~apple~CloudDocs/Helper/backend/backend/docs/intent_combinations.csv
A20: calendar | B20: list | C20: relative | D20: 7d | E20: info | F20: {} | G20: =A20&"|"&B20&"|"&C20&"|"&IF(D20="","(none)",D20) | H20: =--(C20="all") | I20: =--(C20="relative") | J20: =IF(AND(A20<>"",B20<>"",C20<>""),1,0) | K20: =COUNTIF($G$2:$G$496,G20) | L20: =IF(K20>1,1,0) | M20: file:///Users/sagalilja/Library/Mobile%20Documents/com~apple~CloudDocs/Helper/backend/backend/docs/intent_combinations.csv
A21: calendar | B21: list | C21: relative | D21: 30d | E21: info | F21: {} | G21: =A21&"|"&B21&"|"&C21&"|"&IF(D21="","(none)",D21) | H21: =--(C21="all") | I21: =--(C21="relative") | J21: =IF(AND(A21<>"",B21<>"",C21<>""),1,0) | K21: =COUNTIF($G$2:$G$496,G21) | L21: =IF(K21>1,1,0) | M21: file:///Users/sagalilja/Library/Mobile%20Documents/com~apple~CloudDocs/Helper/backend/backend/docs/intent_combinations.csv
A22: calendar | B22: list | C22: relative | D22: 3m | E22: info | F22: {} | G22: =A22&"|"&B22&"|"&C22&"|"&IF(D22="","(none)",D22) | H22: =--(C22="all") | I22: =--(C22="relative") | J22: =IF(AND(A22<>"",B22<>"",C22<>""),1,0) | K22: =COUNTIF($G$2:$G$496,G22) | L22: =IF(K22>1,1,0) | M22: file:///Users/sagalilja/Library/Mobile%20Documents/com~apple~CloudDocs/Helper/backend/backend/docs/intent_combinations.csv
A23: calendar | B23: list | C23: relative | D23: 1y | E23: info | F23: {} | G23: =A23&"|"&B23&"|"&C23&"|"&IF(D23="","(none)",D23) | H23: =--(C23="all") | I23: =--(C23="relative") | J23: =IF(AND(A23<>"",B23<>"",C23<>""),1,0) | K23: =COUNTIF($G$2:$G$496,G23) | L23: =IF(K23>1,1,0) | M23: file:///Users/sagalilja/Library/Mobile%20Documents/com~apple~CloudDocs/Helper/backend/backend/docs/intent_combinations.csv
A24: calendar | B24: exists | C24: all | E24: info | F24: {} | G24: =A24&"|"&B24&"|"&C24&"|"&IF(D24="","(none)",D24) | H24: =--(C24="all") | I24: =--(C24="relative") | J24: =IF(AND(A24<>"",B24<>"",C24<>""),1,0) | K24: =COUNTIF($G$2:$G$496,G24) | L24: =IF(K24>1,1,0) | M24: file:///Users/sagalilja/Library/Mobile%20Documents/com~apple~CloudDocs/Helper/backend/backend/docs/intent_combinations.csv
A25: calendar | B25: exists | C25: relative | D25: today | E25: info | F25: {} | G25: =A25&"|"&B25&"|"&C25&"|"&IF(D25="","(none)",D25) | H25: =--(C25="all") | I25: =--(C25="relative") | J25: =IF(AND(A25<>"",B25<>"",C25<>""),1,0) | K25: =COUNTIF($G$2:$G$496,G25) | L25: =IF(K25>1,1,0) | M25: file:///Users/sagalilja/Library/Mobile%20Documents/com~apple~CloudDocs/Helper/backend/backend/docs/intent_combinations.csv
A26: calendar | B26: exists | C26: relative | D26: today_morning | E26: info | F26: {} | G26: =A26&"|"&B26&"|"&C26&"|"&IF(D26="","(none)",D26) | H26: =--(C26="all") | I26: =--(C26="relative") | J26: =IF(AND(A26<>"",B26<>"",C26<>""),1,0) | K26: =COUNTIF($G$2:$G$496,G26) | L26: =IF(K26>1,1,0) | M26: file:///Users/sagalilja/Library/Mobile%20Documents/com~apple~CloudDocs/Helper/backend/backend/docs/intent_combinations.csv
A27: calendar | B27: exists | C27: relative | D27: today_day | E27: info | F27: {} | G27: =A27&"|"&B27&"|"&C27&"|"&IF(D27="","(none)",D27) | H27: =--(C27="all") | I27: =--(C27="relative") | J27: =IF(AND(A27<>"",B27<>"",C27<>""),1,0) | K27: =COUNTIF($G$2:$G$496,G27) | L27: =IF(K27>1,1,0) | M27: file:///Users/sagalilja/Library/Mobile%20Documents/com~apple~CloudDocs/Helper/backend/backend/docs/intent_combinations.csv
A28: calendar | B28: exists | C28: relative | D28: today_afternoon | E28: info | F28: {} | G28: =A28&"|"&B28&"|"&C28&"|"&IF(D28="","(none)",D28) | H28: =--(C28="all") | I28: =--(C28="relative") | J28: =IF(AND(A28<>"",B28<>"",C28<>""),1,0) | K28: =COUNTIF($G$2:$G$496,G28) | L28: =IF(K28>1,1,0) | M28: file:///Users/sagalilja/Library/Mobile%20Documents/com~apple~CloudDocs/Helper/backend/backend/docs/intent_combinations.csv
A29: calendar | B29: exists | C29: relative | D29: today_evening | E29: info | F29: {} | G29: =A29&"|"&B29&"|"&C29&"|"&IF(D29="","(none)",D29) | H29: =--(C29="all") | I29: =--(C29="relative") | J29: =IF(AND(A29<>"",B29<>"",C29<>""),1,0) | K29: =COUNTIF($G$2:$G$496,G29) | L29: =IF(K29>1,1,0) | M29: file:///Users/sagalilja/Library/Mobile%20Documents/com~apple~CloudDocs/Helper/backend/backend/docs/intent_combinations.csv
A30: calendar | B30: exists | C30: relative | D30: tomorrow_morning | E30: info | F30: {} | G30: =A30&"|"&B30&"|"&C30&"|"&IF(D30="","(none)",D30) | H30: =--(C30="all") | I30: =--(C30="relative") | J30: =IF(AND(A30<>"",B30<>"",C30<>""),1,0) | K30: =COUNTIF($G$2:$G$496,G30) | L30: =IF(K30>1,1,0) | M30: file:///Users/sagalilja/Library/Mobile%20Documents/com~apple~CloudDocs/Helper/backend/backend/docs/intent_combinations.csv
A31: calendar | B31: exists | C31: relative | D31: 7d | E31: info | F31: {} | G31: =A31&"|"&B31&"|"&C31&"|"&IF(D31="","(none)",D31) | H31: =--(C31="all") | I31: =--(C31="relative") | J31: =IF(AND(A31<>"",B31<>"",C31<>""),1,0) | K31: =COUNTIF($G$2:$G$496,G31) | L31: =IF(K31>1,1,0) | M31: file:///Users/sagalilja/Library/Mobile%20Documents/com~apple~CloudDocs/Helper/backend/backend/docs/intent_combinations.csv
A32: calendar | B32: exists | C32: relative | D32: 30d | E32: info | F32: {} | G32: =A32&"|"&B32&"|"&C32&"|"&IF(D32="","(none)",D32) | H32: =--(C32="all") | I32: =--(C32="relative") | J32: =IF(AND(A32<>"",B32<>"",C32<>""),1,0) | K32: =COUNTIF($G$2:$G$496,G32) | L32: =IF(K32>1,1,0) | M32: file:///Users/sagalilja/Library/Mobile%20Documents/com~apple~CloudDocs/Helper/backend/backend/docs/intent_combinations.csv
A33: calendar | B33: exists | C33: relative | D33: 3m | E33: info | F33: {} | G33: =A33&"|"&B33&"|"&C33&"|"&IF(D33="","(none)",D33) | H33: =--(C33="all") | I33: =--(C33="relative") | J33: =IF(AND(A33<>"",B33<>"",C33<>""),1,0) | K33: =COUNTIF($G$2:$G$496,G33) | L33: =IF(K33>1,1,0) | M33: file:///Users/sagalilja/Library/Mobile%20Documents/com~apple~CloudDocs/Helper/backend/backend/docs/intent_combinations.csv
A34: calendar | B34: exists | C34: relative | D34: 1y | E34: info | F34: {} | G34: =A34&"|"&B34&"|"&C34&"|"&IF(D34="","(none)",D34) | H34: =--(C34="all") | I34: =--(C34="relative") | J34: =IF(AND(A34<>"",B34<>"",C34<>""),1,0) | K34: =COUNTIF($G$2:$G$496,G34) | L34: =IF(K34>1,1,0) | M34: file:///Users/sagalilja/Library/Mobile%20Documents/com~apple~CloudDocs/Helper/backend/backend/docs/intent_combinations.csv
A35: calendar | B35: sum | C35: all | E35: info | F35: {} | G35: =A35&"|"&B35&"|"&C35&"|"&IF(D35="","(none)",D35) | H35: =--(C35="all") | I35: =--(C35="relative") | J35: =IF(AND(A35<>"",B35<>"",C35<>""),1,0) | K35: =COUNTIF($G$2:$G$496,G35) | L35: =IF(K35>1,1,0) | M35: file:///Users/sagalilja/Library/Mobile%20Documents/com~apple~CloudDocs/Helper/backend/backend/docs/intent_combinations.csv
A36: calendar | B36: sum | C36: relative | D36: today | E36: info | F36: {} | G36: =A36&"|"&B36&"|"&C36&"|"&IF(D36="","(none)",D36) | H36: =--(C36="all") | I36: =--(C36="relative") | J36: =IF(AND(A36<>"",B36<>"",C36<>""),1,0) | K36: =COUNTIF($G$2:$G$496,G36) | L36: =IF(K36>1,1,0) | M36: file:///Users/sagalilja/Library/Mobile%20Documents/com~apple~CloudDocs/Helper/backend/backend/docs/intent_combinations.csv
A37: calendar | B37: sum | C37: relative | D37: today_morning | E37: info | F37: {} | G37: =A37&"|"&B37&"|"&C37&"|"&IF(D37="","(none)",D37) | H37: =--(C37="all") | I37: =--(C37="relative") | J37: =IF(AND(A37<>"",B37<>"",C37<>""),1,0) | K37: =COUNTIF($G$2:$G$496,G37) | L37: =IF(K37>1,1,0) | M37: file:///Users/sagalilja/Library/Mobile%20Documents/com~apple~CloudDocs/Helper/backend/backend/docs/intent_combinations.csv
A38: calendar | B38: sum | C38: relative | D38: today_day | E38: info | F38: {} | G38: =A38&"|"&B38&"|"&C38&"|"&IF(D38="","(none)",D38) | H38: =--(C38="all") | I38: =--(C38="relative") | J38: =IF(AND(A38<>"",B38<>"",C38<>""),1,0) | K38: =COUNTIF($G$2:$G$496,G38) | L38: =IF(K38>1,1,0) | M38: file:///Users/sagalilja/Library/Mobile%20Documents/com~apple~CloudDocs/Helper/backend/backend/docs/intent_combinations.csv
A39: calendar | B39: sum | C39: relative | D39: today_afternoon | E39: info | F39: {} | G39: =A39&"|"&B39&"|"&C39&"|"&IF(D39="","(none)",D39) | H39: =--(C39="all") | I39: =--(C39="relative") | J39: =IF(AND(A39<>"",B39<>"",C39<>""),1,0) | K39: =COUNTIF($G$2:$G$496,G39) | L39: =IF(K39>1,1,0) | M39: file:///Users/sagalilja/Library/Mobile%20Documents/com~apple~CloudDocs/Helper/backend/backend/docs/intent_combinations.csv
A40: calendar | B40: sum | C40: relative | D40: today_evening | E40: info | F40: {} | G40: =A40&"|"&B40&"|"&C40&"|"&IF(D40="","(none)",D40) | H40: =--(C40="all") | I40: =--(C40="relative") | J40: =IF(AND(A40<>"",B40<>"",C40<>""),1,0) | K40: =COUNTIF($G$2:$G$496,G40) | L40: =IF(K40>1,1,0) | M40: file:///Users/sagalilja/Library/Mobile%20Documents/com~apple~CloudDocs/Helper/backend/backend/docs/intent_combinations.csv
...

Sheet Summary
A1: Intent Combination Coverage Tracker
A3: Model Inputs
A4: Domain count | B4: 9
A5: Operation count | B5: 5
A6: Time buckets per domain+operation | B6: 11
A8: Validation
A9: Expected total combinations | B9: =B4*B5*B6
A10: Actual combinations (rows) | B10: =COUNTA(IntentCombinations!$A:$A)-1
A11: Duplicate combinations | B11: =SUM(IntentCombinations!$L$2:$L$496)
A12: Coverage status | B12: =IF(AND(B9=B10,B11=0),"OK","CHECK")
A14: Domain \ Operation | B14: count | C14: list | D14: exists | E14: sum | F14: latest | G14: Row Total | H14: Expected | I14: Variance
A15: calendar | B15: =COUNTIFS(IntentCombinations!$A:$A,$A15,IntentCombinations!$B:$B,B$14) | C15: =COUNTIFS(IntentCombinations!$A:$A,$A15,IntentCombinations!$B:$B,C$14) | D15: =COUNTIFS(IntentCombinations!$A:$A,$A15,IntentCombinations!$B:$B,D$14) | E15: =COUNTIFS(IntentCombinations!$A:$A,$A15,IntentCombinations!$B:$B,E$14) | F15: =COUNTIFS(IntentCombinations!$A:$A,$A15,IntentCombinations!$B:$B,F$14) | G15: =SUM(B15:F15) | H15: =$B$6*COUNTA(B14:F14) | I15: =G15-H15
A16: reminders | B16: =COUNTIFS(IntentCombinations!$A:$A,$A16,IntentCombinations!$B:$B,B$14) | C16: =COUNTIFS(IntentCombinations!$A:$A,$A16,IntentCombinations!$B:$B,C$14) | D16: =COUNTIFS(IntentCombinations!$A:$A,$A16,IntentCombinations!$B:$B,D$14) | E16: =COUNTIFS(IntentCombinations!$A:$A,$A16,IntentCombinations!$B:$B,E$14) | F16: =COUNTIFS(IntentCombinations!$A:$A,$A16,IntentCombinations!$B:$B,F$14) | G16: =SUM(B16:F16) | H16: =$B$6*COUNTA(B14:F14) | I16: =G16-H16
A17: mail | B17: =COUNTIFS(IntentCombinations!$A:$A,$A17,IntentCombinations!$B:$B,B$14) | C17: =COUNTIFS(IntentCombinations!$A:$A,$A17,IntentCombinations!$B:$B,C$14) | D17: =COUNTIFS(IntentCombinations!$A:$A,$A17,IntentCombinations!$B:$B,D$14) | E17: =COUNTIFS(IntentCombinations!$A:$A,$A17,IntentCombinations!$B:$B,E$14) | F17: =COUNTIFS(IntentCombinations!$A:$A,$A17,IntentCombinations!$B:$B,F$14) | G17: =SUM(B17:F17) | H17: =$B$6*COUNTA(B14:F14) | I17: =G17-H17
A18: notes | B18: =COUNTIFS(IntentCombinations!$A:$A,$A18,IntentCombinations!$B:$B,B$14) | C18: =COUNTIFS(IntentCombinations!$A:$A,$A18,IntentCombinations!$B:$B,C$14) | D18: =COUNTIFS(IntentCombinations!$A:$A,$A18,IntentCombinations!$B:$B,D$14) | E18: =COUNTIFS(IntentCombinations!$A:$A,$A18,IntentCombinations!$B:$B,E$14) | F18: =COUNTIFS(IntentCombinations!$A:$A,$A18,IntentCombinations!$B:$B,F$14) | G18: =SUM(B18:F18) | H18: =$B$6*COUNTA(B14:F14) | I18: =G18-H18
A19: files | B19: =COUNTIFS(IntentCombinations!$A:$A,$A19,IntentCombinations!$B:$B,B$14) | C19: =COUNTIFS(IntentCombinations!$A:$A,$A19,IntentCombinations!$B:$B,C$14) | D19: =COUNTIFS(IntentCombinations!$A:$A,$A19,IntentCombinations!$B:$B,D$14) | E19: =COUNTIFS(IntentCombinations!$A:$A,$A19,IntentCombinations!$B:$B,E$14) | F19: =COUNTIFS(IntentCombinations!$A:$A,$A19,IntentCombinations!$B:$B,F$14) | G19: =SUM(B19:F19) | H19: =$B$6*COUNTA(B14:F14) | I19: =G19-H19
A20: photos | B20: =COUNTIFS(IntentCombinations!$A:$A,$A20,IntentCombinations!$B:$B,B$14) | C20: =COUNTIFS(IntentCombinations!$A:$A,$A20,IntentCombinations!$B:$B,C$14) | D20: =COUNTIFS(IntentCombinations!$A:$A,$A20,IntentCombinations!$B:$B,D$14) | E20: =COUNTIFS(IntentCombinations!$A:$A,$A20,IntentCombinations!$B:$B,E$14) | F20: =COUNTIFS(IntentCombinations!$A:$A,$A20,IntentCombinations!$B:$B,F$14) | G20: =SUM(B20:F20) | H20: =$B$6*COUNTA(B14:F14) | I20: =G20-H20
A21: contacts | B21: =COUNTIFS(IntentCombinations!$A:$A,$A21,IntentCombinations!$B:$B,B$14) | C21: =COUNTIFS(IntentCombinations!$A:$A,$A21,IntentCombinations!$B:$B,C$14) | D21: =COUNTIFS(IntentCombinations!$A:$A,$A21,IntentCombinations!$B:$B,D$14) | E21: =COUNTIFS(IntentCombinations!$A:$A,$A21,IntentCombinations!$B:$B,E$14) | F21: =COUNTIFS(IntentCombinations!$A:$A,$A21,IntentCombinations!$B:$B,F$14) | G21: =SUM(B21:F21) | H21: =$B$6*COUNTA(B14:F14) | I21: =G21-H21
A22: location | B22: =COUNTIFS(IntentCombinations!$A:$A,$A22,IntentCombinations!$B:$B,B$14) | C22: =COUNTIFS(IntentCombinations!$A:$A,$A22,IntentCombinations!$B:$B,C$14) | D22: =COUNTIFS(IntentCombinations!$A:$A,$A22,IntentCombinations!$B:$B,D$14) | E22: =COUNTIFS(IntentCombinations!$A:$A,$A22,IntentCombinations!$B:$B,E$14) | F22: =COUNTIFS(IntentCombinations!$A:$A,$A22,IntentCombinations!$B:$B,F$14) | G22: =SUM(B22:F22) | H22: =$B$6*COUNTA(B14:F14) | I22: =G22-H22
A23: memory | B23: =COUNTIFS(IntentCombinations!$A:$A,$A23,IntentCombinations!$B:$B,B$14) | C23: =COUNTIFS(IntentCombinations!$A:$A,$A23,IntentCombinations!$B:$B,C$14) | D23: =COUNTIFS(IntentCombinations!$A:$A,$A23,IntentCombinations!$B:$B,D$14) | E23: =COUNTIFS(IntentCombinations!$A:$A,$A23,IntentCombinations!$B:$B,E$14) | F23: =COUNTIFS(IntentCombinations!$A:$A,$A23,IntentCombinations!$B:$B,F$14) | G23: =SUM(B23:F23) | H23: =$B$6*COUNTA(B14:F14) | I23: =G23-H23
A24: Column Total | B24: =SUM(B15:B23) | C24: =SUM(C15:C23) | D24: =SUM(D15:D23) | E24: =SUM(E15:E23) | F24: =SUM(F15:F23) | G24: =SUM(G15:G23) | H24: =$B$9 | I24: =G24-H24

Sheet Sources
A1: source_name | B1: url | C1: notes
A2: Domain/operation source | B2: file:///Users/sagalilja/Library/Mobile%20Documents/com~apple~CloudDocs/Helper/backend/docs/domain_operation_table.csv | C2: Base domain-operation coverage
A3: Intent combinations source | B3: file:///Users/sagalilja/Library/Mobile%20Documents/com~apple~CloudDocs/Helper/backend/backend/docs/intent_combinations.csv | C3: Full domain-operation-time combinations
A4: Workbook generated_at_utc | B4: 2026-02-21T23:24:52+00:00 | C4: Generation timestamp
